Traceback (most recent call last):
  File "C:\Users\Antho\AppData\Local\Programs\Python\Python311\Lib\site-packages\urllib3\connection.py", line 174, in _new_conn
    conn = connection.create_connection(
           ^^^^^^^^^^^^^^^^^^^^^^^^^^^^^
  File "C:\Users\Antho\AppData\Local\Programs\Python\Python311\Lib\site-packages\urllib3\util\connection.py", line 72, in create_connection
    for res in socket.getaddrinfo(host, port, family, socket.SOCK_STREAM):
               ^^^^^^^^^^^^^^^^^^^^^^^^^^^^^^^^^^^^^^^^^^^^^^^^^^^^^^^^^^
  File "C:\Users\Antho\AppData\Local\Programs\Python\Python311\Lib\socket.py", line 962, in getaddrinfo
    for res in _socket.getaddrinfo(host, port, family, type, proto, flags):
               ^^^^^^^^^^^^^^^^^^^^^^^^^^^^^^^^^^^^^^^^^^^^^^^^^^^^^^^^^^^
socket.gaierror: [Errno 11001] getaddrinfo failed

During handling of the above exception, another exception occurred:

Traceback (most recent call last):
  File "C:\Users\Antho\AppData\Local\Programs\Python\Python311\Lib\site-packages\urllib3\connectionpool.py", line 714, in urlopen
    httplib_response = self._make_request(
                       ^^^^^^^^^^^^^^^^^^^
  File "C:\Users\Antho\AppData\Local\Programs\Python\Python311\Lib\site-packages\urllib3\connectionpool.py", line 403, in _make_request
    self._validate_conn(conn)
  File "C:\Users\Antho\AppData\Local\Programs\Python\Python311\Lib\site-packages\urllib3\connectionpool.py", line 1053, in _validate_conn
    conn.connect()
  File "C:\Users\Antho\AppData\Local\Programs\Python\Python311\Lib\site-packages\urllib3\connection.py", line 363, in connect
    self.sock = conn = self._new_conn()
                       ^^^^^^^^^^^^^^^^
  File "C:\Users\Antho\AppData\Local\Programs\Python\Python311\Lib\site-packages\urllib3\connection.py", line 186, in _new_conn
    raise NewConnectionError(
urllib3.exceptions.NewConnectionError: <urllib3.connection.HTTPSConnection object at 0x0000028479CAAE50>: Failed to establish a new connection: [Errno 11001] getaddrinfo failed

During handling of the above exception, another exception occurred:

Traceback (most recent call last):
  File "C:\Users\Antho\AppData\Local\Programs\Python\Python311\Lib\site-packages\requests\adapters.py", line 486, in send
    resp = conn.urlopen(
           ^^^^^^^^^^^^^
  File "C:\Users\Antho\AppData\Local\Programs\Python\Python311\Lib\site-packages\urllib3\connectionpool.py", line 798, in urlopen
    retries = retries.increment(
              ^^^^^^^^^^^^^^^^^^
  File "C:\Users\Antho\AppData\Local\Programs\Python\Python311\Lib\site-packages\urllib3\util\retry.py", line 592, in increment
    raise MaxRetryError(_pool, url, error or ResponseError(cause))
urllib3.exceptions.MaxRetryError: HTTPSConnectionPool(host='api.exampleexchange.com', port=443): Max retries exceeded with url: /coins/Bitcoin/price (Caused by NewConnectionError('<urllib3.connection.HTTPSConnection object at 0x0000028479CAAE50>: Failed to establish a new connection: [Errno 11001] getaddrinfo failed'))

During handling of the above exception, another exception occurred:

Traceback (most recent call last):
  File "C:\Users\Antho\temp.py", line 29, in fetch_price_data
    response = requests.get(url, headers=headers)
               ^^^^^^^^^^^^^^^^^^^^^^^^^^^^^^^^^^
  File "C:\Users\Antho\AppData\Local\Programs\Python\Python311\Lib\site-packages\requests\api.py", line 73, in get
    return request("get", url, params=params, **kwargs)
           ^^^^^^^^^^^^^^^^^^^^^^^^^^^^^^^^^^^^^^^^^^^^
  File "C:\Users\Antho\AppData\Local\Programs\Python\Python311\Lib\site-packages\requests\api.py", line 59, in request
    return session.request(method=method, url=url, **kwargs)
           ^^^^^^^^^^^^^^^^^^^^^^^^^^^^^^^^^^^^^^^^^^^^^^^^^
  File "C:\Users\Antho\AppData\Local\Programs\Python\Python311\Lib\site-packages\requests\sessions.py", line 589, in request
    resp = self.send(prep, **send_kwargs)
           ^^^^^^^^^^^^^^^^^^^^^^^^^^^^^^
  File "C:\Users\Antho\AppData\Local\Programs\Python\Python311\Lib\site-packages\requests\sessions.py", line 703, in send
    r = adapter.send(request, **kwargs)
        ^^^^^^^^^^^^^^^^^^^^^^^^^^^^^^^
  File "C:\Users\Antho\AppData\Local\Programs\Python\Python311\Lib\site-packages\requests\adapters.py", line 519, in send
    raise ConnectionError(e, request=request)
requests.exceptions.ConnectionError: HTTPSConnectionPool(host='api.exampleexchange.com', port=443): Max retries exceeded with url: /coins/Bitcoin/price (Caused by NewConnectionError('<urllib3.connection.HTTPSConnection object at 0x0000028479CAAE50>: Failed to establish a new connection: [Errno 11001] getaddrinfo failed'))

The above exception was the direct cause of the following exception:

Traceback (most recent call last):
  File "C:\Users\Antho\temp.py", line 132, in <module>
    main()
  File "C:\Users\Antho\temp.py", line 118, in main
    tracker.add_cryptocurrency("Bitcoin")
  File "C:\Users\Antho\temp.py", line 37, in add_cryptocurrency
    price_data = self.fetch_price_data(cryptocurrency)
                 ^^^^^^^^^^^^^^^^^^^^^^^^^^^^^^^^^^^^^
  File "C:\Users\Antho\temp.py", line 34, in fetch_price_data
    raise Exception(f"Error fetching price data for {cryptocurrency}") from e
Exception: Error fetching price data for Bitcoin
